<?xml version="1.0" ?>
<robot name="8dofarm">
  
  <material name="red">
    <color rgba="1.0 0.0 0.0 1.0"/>
  </material>
  <material name="green">
    <color rgba="0.0 1.0 0.0 1.0"/>
  </material>
  <material name="blue">
    <color rgba="0.0 0.0 1.0 1.0"/>
  </material>
  


  <joint name="base_footprint_2_base0" type="fixed">
    <parent link="base_footprint"/>
    <child link="base0"/>
    <origin rpy="0 0 0" xyz="0 0 0.05"/>
    
  </joint>
  


  <!-- base_link -->
  <link name="base0">
    <collision>
      <origin rpy="0 0 0" xyz="0 0 0.0"/>
      <geometry>
        <box size="0.5 0.5 0.01"/>
      </geometry>
    </collision>
    <visual>
      <origin rpy="0 0 0" xyz="0 0 0.0"/>
      <geometry>
        <box size="0.05 0.05 0.01"/>
      </geometry>
      <material name="blue"/>
    </visual>
    <inertial>
      <origin rpy="0 0 0" xyz="0 0 0.0"/>
      <mass value="0"/>
      <inertia ixx="0" ixy="0" ixz="0" iyy="0" iyz="0" izz="0"/>
    </inertial>
  </link>

  
  <joint name="base0_2_Link1" type="fixed">
    <parent link="base0"/>
    <child link="Link1"/>
    <origin rpy="0 0 0" xyz="0 0 0"/>
    
  </joint>
  


  <!-- Link1 -->
  <link name="Link1">
    <collision>
      <origin rpy="0 0 0" xyz="0 0 0.05"/>
      <geometry>
        <box size="0.05 0.05 0.1"/>
      </geometry>
    </collision>
    <visual>
      <origin rpy="0 0 0" xyz="0 0 0.05"/>
      <geometry>
        <box size="0.05 0.05 0.1"/>
      </geometry>
      <material name="red"/>
    </visual>
    <inertial>
      <origin rpy="0 0 0" xyz="0 0 0.05"/>
      <mass value="1"/>
      <inertia ixx="1" ixy="0" ixz="0" iyy="1" iyz="0" izz="1"/>
    </inertial>
  </link>

  
  <joint name="Link1_2_Link2" type="revolute">
    <parent link="Link1"/>
    <child link="Link2"/>
    <origin rpy="0 0 0" xyz="0 0 0.1"/>
    
    <axis xyz="0 0 1"/>
    <limit effort="30" lower="-2.616" upper="2.617" velocity="1.571"/>
    
  </joint>
  
  <gazebo reference="Link1">
    <material>Gazebo/Red</material>
  </gazebo>
  <transmission name="trans1">
    <type>transmission_interface/SimpleTransmission</type>
    <joint name="Link1_2_Link2"> 
      <hardwareInterface>hardware_interface/EffortJointInterface</hardwareInterface>
    </joint>
    <actuator name="motor1">
       <hardwareInterface>EffortJointInterface</hardwareInterface>
      <mechanicalReduction>1</mechanicalReduction>
    </actuator>
  </transmission>


  <!-- Link2 -->
  <link name="Link2">
    <collision>
      <origin rpy="0 0 0" xyz="0 0 0"/>
      <geometry>
        <box size="0.05 0.1 0.05"/>
      </geometry>
    </collision>
    <visual>
      <origin rpy="0 0 0" xyz="0 0 0"/>
      <geometry>
        <box size="0.05 0.1 0.05"/>
      </geometry>
      <material name="green"/>
    </visual>
    <inertial>
      <origin rpy="0 0 0" xyz="0 0 0"/>
      <mass value="1"/>
      <inertia ixx="1" ixy="0" ixz="0" iyy="1" iyz="0" izz="1"/>
    </inertial>
  </link>

  
  <joint name="Link2_2_Link3" type="revolute">
    <parent link="Link2"/>
    <child link="Link3"/>
    <origin rpy="0 0 0" xyz="0 0 0"/>
    
    <axis xyz="0 1 0"/>
    <limit effort="30" lower="-2.616" upper="2.617" velocity="1.571"/>
    
  </joint>
  
  <gazebo reference="Link2">
    <material>Gazebo/Green</material>
  </gazebo>
  <transmission name="trans2">
    <type>transmission_interface/SimpleTransmission</type>
    <joint name="Link2_2_Link3"> 
      <hardwareInterface>hardware_interface/EffortJointInterface</hardwareInterface>
    </joint>
    <actuator name="motor2">
       <hardwareInterface>EffortJointInterface</hardwareInterface>
      <mechanicalReduction>1</mechanicalReduction>
    </actuator>
  </transmission>


  <!-- Link3 -->
  <link name="Link3">
    <collision>
      <origin rpy="0 0 0" xyz="0 0 0.05"/>
      <geometry>
        <box size="0.05 0.05 0.1"/>
      </geometry>
    </collision>
    <visual>
      <origin rpy="0 0 0" xyz="0 0 0.05"/>
      <geometry>
        <box size="0.05 0.05 0.1"/>
      </geometry>
      <material name="blue"/>
    </visual>
    <inertial>
      <origin rpy="0 0 0" xyz="0 0 0.05"/>
      <mass value="1"/>
      <inertia ixx="1" ixy="0" ixz="0" iyy="1" iyz="0" izz="1"/>
    </inertial>
  </link>

  
  <joint name="Link3_2_Link4" type="revolute">
    <parent link="Link3"/>
    <child link="Link4"/>
    <origin rpy="0 0 0" xyz="0 0 0.1"/>
    
    <axis xyz="0 0 1"/>
    <limit effort="30" lower="-2.616" upper="2.617" velocity="1.571"/>
    
  </joint>
  
<gazebo reference="Link3">
    <material>Gazebo/Blue</material>
  </gazebo>
  <transmission name="trans3">
    <type>transmission_interface/SimpleTransmission</type>
    <joint name="Link3_2_Link4"> 
      <hardwareInterface>hardware_interface/EffortJointInterface</hardwareInterface>
    </joint>
    <actuator name="motor3">
       <hardwareInterface>EffortJointInterface</hardwareInterface>
      <mechanicalReduction>1</mechanicalReduction>
    </actuator>
  </transmission>


  <!-- Link4 -->
  <link name="Link4">
    <collision>
      <origin rpy="0 0 0" xyz="0 0 0"/>
      <geometry>
        <box size="0.05 0.1 0.05"/>
      </geometry>
    </collision>
    <visual>
      <origin rpy="0 0 0" xyz="0 0 0"/>
      <geometry>
        <box size="0.05 0.1 0.05"/>
      </geometry>
      <material name="green"/>
    </visual>
    <inertial>
      <origin rpy="0 0 0" xyz="0 0 0"/>
      <mass value="1"/>
      <inertia ixx="1" ixy="0" ixz="0" iyy="1" iyz="0" izz="1"/>
    </inertial>
  </link>

  
  <joint name="Link4_2_Link5" type="revolute">
    <parent link="Link4"/>
    <child link="Link5"/>
    <origin rpy="0 0 0" xyz="0 0 0"/>
    
    <axis xyz="0 1 0"/>
    <limit effort="30" lower="-2.616" upper="2.617" velocity="1.571"/>
    
  </joint>
  
  <gazebo reference="Link4">
    <material>Gazebo/Green</material>
  </gazebo>
  <transmission name="trans4">
    <type>transmission_interface/SimpleTransmission</type>
    <joint name="Link4_2_Link5"> 
      <hardwareInterface>hardware_interface/EffortJointInterface</hardwareInterface>
    </joint>
    <actuator name="motor4">
       <hardwareInterface>EffortJointInterface</hardwareInterface>
      <mechanicalReduction>1</mechanicalReduction>
    </actuator>
  </transmission>


  <!-- Link5 -->
  <link name="Link5">
    <collision>
      <origin rpy="0 0 0" xyz="0 0 0.05"/>
      <geometry>
        <box size="0.05 0.05 0.1"/>
      </geometry>
    </collision>
    <visual>
      <origin rpy="0 0 0" xyz="0 0 0.05"/>
      <geometry>
        <box size="0.05 0.05 0.1"/>
      </geometry>
      <material name="red"/>
    </visual>
    <inertial>
      <origin rpy="0 0 0" xyz="0 0 0.05"/>
      <mass value="1"/>
      <inertia ixx="1" ixy="0" ixz="0" iyy="1" iyz="0" izz="1"/>
    </inertial>
  </link>

  
  <joint name="Link5_2_Link6" type="revolute">
    <parent link="Link5"/>
    <child link="Link6"/>
    <origin rpy="0 0 0" xyz="0 0 0.1"/>
    
    <axis xyz="0 0 1"/>
    <limit effort="30" lower="-2.616" upper="2.617" velocity="1.571"/>
    
  </joint>

 <gazebo reference="Link5">
    <material>Gazebo/Red</material>
  </gazebo>
  <transmission name="trans5">
    <type>transmission_interface/SimpleTransmission</type>
    <joint name="Link5_2_Link6"> 
      <hardwareInterface>hardware_interface/EffortJointInterface</hardwareInterface>
    </joint>
    <actuator name="motor5">
       <hardwareInterface>EffortJointInterface</hardwareInterface>
      <mechanicalReduction>1</mechanicalReduction>
    </actuator>
  </transmission>

  


  <!-- Link6 -->
  <link name="Link6">
    <collision>
      <origin rpy="0 0 0" xyz="0 0 0"/>
      <geometry>
        <box size="0.05 0.1 0.05"/>
      </geometry>
    </collision>
    <visual>
      <origin rpy="0 0 0" xyz="0 0 0"/>
      <geometry>
        <box size="0.05 0.1 0.05"/>
      </geometry>
      <material name="green"/>
    </visual>
    <inertial>
      <origin rpy="0 0 0" xyz="0 0 0"/>
      <mass value="1"/>
      <inertia ixx="1" ixy="0" ixz="0" iyy="1" iyz="0" izz="1"/>
    </inertial>
  </link>

  
  <joint name="Link6_2_Link7" type="revolute">
    <parent link="Link6"/>
    <child link="Link7"/>
    <origin rpy="0 0 0" xyz="0 0 0"/>
    
    <axis xyz="0 1 0"/>
    <limit effort="30" lower="-2.616" upper="2.617" velocity="1.571"/>
    
  </joint>
  
 <gazebo reference="Link6">
    <material>Gazebo/Green</material>
  </gazebo>
  <transmission name="trans6">
    <type>transmission_interface/SimpleTransmission</type>
    <joint name="Link6_2_Link7"> 
      <hardwareInterface>hardware_interface/EffortJointInterface</hardwareInterface>
    </joint>
    <actuator name="motor6">
       <hardwareInterface>EffortJointInterface</hardwareInterface>
      <mechanicalReduction>1</mechanicalReduction>
    </actuator>
  </transmission>


  <!-- Link7 -->
  <link name="Link7">
    <collision>
      <origin rpy="0 0 0" xyz="0 0 0.05"/>
      <geometry>
        <box size="0.05 0.05 0.1"/>
      </geometry>
    </collision>
    <visual>
      <origin rpy="0 0 0" xyz="0 0 0.05"/>
      <geometry>
        <box size="0.05 0.05 0.1"/>
      </geometry>
      <material name="blue"/>
    </visual>
    <inertial>
      <origin rpy="0 0 0" xyz="0 0 0.05"/>
      <mass value="1"/>
      <inertia ixx="1" ixy="0" ixz="0" iyy="1" iyz="0" izz="1"/>
    </inertial>
  </link>

  
  <joint name="Link7_2_Link8" type="revolute">
    <parent link="Link7"/>
    <child link="Link8"/>
    <origin rpy="0 0 0" xyz="0 0 0.1"/>
    
    <axis xyz="0 0 1"/>
    <limit effort="30" lower="-2.616" upper="2.617" velocity="1.571"/>
    
  </joint>

 <gazebo reference="Link7">
    <material>Gazebo/Blue</material>
  </gazebo>
  <transmission name="trans7">
    <type>transmission_interface/SimpleTransmission</type>
    <joint name="Link7_2_Link8"> 
      <hardwareInterface>hardware_interface/EffortJointInterface</hardwareInterface>
    </joint>
    <actuator name="motor7">
       <hardwareInterface>EffortJointInterface</hardwareInterface>
      <mechanicalReduction>1</mechanicalReduction>
    </actuator>
  </transmission>  


  <!-- Link8 -->
  <link name="Link8">
    <collision>
      <origin rpy="0 0 0" xyz="0 0 0"/>
      <geometry>
        <box size="0.05 0.1 0.05"/>
      </geometry>
    </collision>
    <visual>
      <origin rpy="0 0 0" xyz="0 0 0"/>
      <geometry>
        <box size="0.05 0.1 0.05"/>
      </geometry>
      <material name="green"/>
    </visual>
    <inertial>
      <origin rpy="0 0 0" xyz="0 0 0"/>
      <mass value="1"/>
      <inertia ixx="1" ixy="0" ixz="0" iyy="1" iyz="0" izz="1"/>
    </inertial>
  </link>

  
  <joint name="Link8_2_Link9" type="revolute">
    <parent link="Link8"/>
    <child link="Link9"/>
    <origin rpy="0 0 0" xyz="0 0 0"/>
    
    <axis xyz="0 1 0"/>
    <limit effort="30" lower="-2.616" upper="2.617" velocity="1.571"/>
    
  </joint>

 <gazebo reference="Link8">
    <material>Gazebo/Green</material>
  </gazebo>
  <transmission name="trans8">
    <type>transmission_interface/SimpleTransmission</type>
    <joint name="Link8_2_Link9"> 
      <hardwareInterface>hardware_interface/EffortJointInterface</hardwareInterface>
    </joint>
    <actuator name="motor8">
       <hardwareInterface>EffortJointInterface</hardwareInterface>
      <mechanicalReduction>1</mechanicalReduction>
    </actuator>
  </transmission>  


  <!-- Link9 -->
  <link name="Link9">
    <collision>
      <origin rpy="0 0 0" xyz="0 0 0.05"/>
      <geometry>
        <box size="0.05 0.05 0.1"/>
      </geometry>
    </collision>
    <visual>
      <origin rpy="0 0 0" xyz="0 0 0.05"/>
      <geometry>
        <box size="0.05 0.05 0.1"/>
      </geometry>
      <material name="red"/>
    </visual>
    <inertial>
      <origin rpy="0 0 0" xyz="0 0 0.05"/>
      <mass value="1"/>
      <inertia ixx="1" ixy="0" ixz="0" iyy="1" iyz="0" izz="1"/>
    </inertial>
  </link>

  <gazebo reference="Link9">
    <material>Gazebo/Red</material>
  </gazebo>
  

<gazebo>
    <plugin name="gazebo_ros_control" filename="libgazebo_ros_control.so">
      <robotNamespace>/8dofarm</robotNamespace>
    </plugin>
</gazebo>

</robot>
